Workbook

Sheet Settings
A1: SETTINGS & CONFIGURATION
A2: Parameter | B2: Value | C2: Description
A3: Tracker Year | B3: 2026 | C3: Year for all calculations
A4: GBP to INR Exchange Rate | B4: 107 | C4: Update manually as needed
A5: INR to GBP Exchange Rate | B5: =IF(B4=0,"",1/B4) -> 0.0093457944 | C5: Auto-calculated
A6: Default Currency | B6: GBP | C6: Your primary currency
A7: Date Format | B7: DD/MM/YYYY | C7: Used across all sheets
A8: Budget Alert Threshold | B8: 0.8 | C8: Warn at 80% of budget (0.0 to 1.0)
A11: Version | B11: 4.0
A12: Last Updated | B12: 46119

Sheet Dashboard
A1: FINANCIAL DASHBOARD
A2: Year 2026 — Quick Snapshot
A4: THIS MONTH
B5: GBP Expenses | C5: =SUMPRODUCT((Expenses!E$3:E$1002="GBP")*(MONTH(Expenses!A$3:A$1002)=MONTH(TODAY()))*(YEAR(Expenses!A$3:A$1002)=2026)*(Expenses!A$3:A$1002<>"")*Expenses!D$3:D$1002) -> 0 | E5: GBP Income | F5: =SUMPRODUCT((Income!D$3:D$502="GBP")*(MONTH(Income!A$3:A$502)=MONTH(TODAY()))*(YEAR(Income!A$3:A$502)=2026)*(Income!A$3:A$502<>"")*Income!C$3:C$502) -> 0 | H5: INR Expenses | I5: =SUMPRODUCT((Expenses!E$3:E$1002="INR")*(MONTH(Expenses!A$3:A$1002)=MONTH(TODAY()))*(YEAR(Expenses!A$3:A$1002)=2026)*(Expenses!A$3:A$1002<>"")*Expenses!D$3:D$1002) -> 0 | K5: INR Income | L5: =SUMPRODUCT((Income!D$3:D$502="INR")*(MONTH(Income!A$3:A$502)=MONTH(TODAY()))*(YEAR(Income!A$3:A$502)=2026)*(Income!A$3:A$502<>"")*Income!C$3:C$502) -> 0
B7: GBP Net Savings | C7: =C5-C6 -> 0 | E7: INR Net Savings | F7: =F5-F6 -> 0
A9: ACCOUNT BALANCES SUMMARY
B10: Total GBP Assets | C10: =Balances!B20 -> 0 | E10: Total GBP CC Debt | F10: =Balances!B21 -> 0 | H10: Total INR Assets | I10: =Balances!B22 -> 0 | K10: Total INR CC Debt | L10: =Balances!B23 -> 0
B12: Combined GBP Equivalent | C12: =Balances!B25 -> 107
A14: YEAR TO DATE
B15: YTD GBP Expenses | C15: =SUMPRODUCT((Expenses!E$3:E$1002="GBP")*(YEAR(Expenses!A$3:A$1002)=2026)*(Expenses!A$3:A$1002<>"")*Expenses!D$3:D$1002) -> 0 | E15: YTD GBP Income | F15: =SUMPRODUCT((Income!D$3:D$502="GBP")*(YEAR(Income!A$3:A$502)=2026)*(Income!A$3:A$502<>"")*Income!C$3:C$502) -> 0 | H15: YTD INR Expenses | I15: =SUMPRODUCT((Expenses!E$3:E$1002="INR")*(YEAR(Expenses!A$3:A$1002)=2026)*(Expenses!A$3:A$1002<>"")*Expenses!D$3:D$1002) -> 0 | K15: YTD INR Income | L15: =SUMPRODUCT((Income!D$3:D$502="INR")*(YEAR(Income!A$3:A$502)=2026)*(Income!A$3:A$502<>"")*Income!C$3:C$502) -> 0
A18: TOP SPENDING CATEGORIES (GBP - This Month)
B19: Rent | C19: =SUMPRODUCT((Expenses!C$3:C$1002="Rent")*(Expenses!E$3:E$1002="GBP")*(MONTH(Expenses!A$3:A$1002)=MONTH(TODAY()))*(YEAR(Expenses!A$3:A$1002)=2026)*(Expenses!A$3:A$1002<>"")*Expenses!D$3:D$1002) -> 0
B20: Transport | C20: =SUMPRODUCT((Expenses!C$3:C$1002="Transport")*(Expenses!E$3:E$1002="GBP")*(MONTH(Expenses!A$3:A$1002)=MONTH(TODAY()))*(YEAR(Expenses!A$3:A$1002)=2026)*(Expenses!A$3:A$1002<>"")*Expenses!D$3:D$1002) -> 0
B21: Travel | C21: =SUMPRODUCT((Expenses!C$3:C$1002="Travel")*(Expenses!E$3:E$1002="GBP")*(MONTH(Expenses!A$3:A$1002)=MONTH(TODAY()))*(YEAR(Expenses!A$3:A$1002)=2026)*(Expenses!A$3:A$1002<>"")*Expenses!D$3:D$1002) -> 0
B22: Shopping | C22: =SUMPRODUCT((Expenses!C$3:C$1002="Shopping")*(Expenses!E$3:E$1002="GBP")*(MONTH(Expenses!A$3:A$1002)=MONTH(TODAY()))*(YEAR(Expenses!A$3:A$1002)=2026)*(Expenses!A$3:A$1002<>"")*Expenses!D$3:D$1002) -> 0
B23: Electronics | C23: =SUMPRODUCT((Expenses!C$3:C$1002="Electronics")*(Expenses!E$3:E$1002="GBP")*(MONTH(Expenses!A$3:A$1002)=MONTH(TODAY()))*(YEAR(Expenses!A$3:A$1002)=2026)*(Expenses!A$3:A$1002<>"")*Expenses!D$3:D$1002) -> 0
B24: Subscriptions | C24: =SUMPRODUCT((Expenses!C$3:C$1002="Subscriptions")*(Expenses!E$3:E$1002="GBP")*(MONTH(Expenses!A$3:A$1002)=MONTH(TODAY()))*(YEAR(Expenses!A$3:A$1002)=2026)*(Expenses!A$3:A$1002<>"")*Expenses!D$3:D$1002) -> 0
B25: Bills | C25: =SUMPRODUCT((Expenses!C$3:C$1002="Bills")*(Expenses!E$3:E$1002="GBP")*(MONTH(Expenses!A$3:A$1002)=MONTH(TODAY()))*(YEAR(Expenses!A$3:A$1002)=2026)*(Expenses!A$3:A$1002<>"")*Expenses!D$3:D$1002) -> 0
B26: Entertainment | C26: =SUMPRODUCT((Expenses!C$3:C$1002="Entertainment")*(Expenses!E$3:E$1002="GBP")*(MONTH(Expenses!A$3:A$1002)=MONTH(TODAY()))*(YEAR(Expenses!A$3:A$1002)=2026)*(Expenses!A$3:A$1002<>"")*Expenses!D$3:D$1002) -> 0
B27: Food and Drinks | C27: =SUMPRODUCT((Expenses!C$3:C$1002="Food and Drinks")*(Expenses!E$3:E$1002="GBP")*(MONTH(Expenses!A$3:A$1002)=MONTH(TODAY()))*(YEAR(Expenses!A$3:A$1002)=2026)*(Expenses!A$3:A$1002<>"")*Expenses!D$3:D$1002) -> 0
B28: Groceries | C28: =SUMPRODUCT((Expenses!C$3:C$1002="Groceries")*(Expenses!E$3:E$1002="GBP")*(MONTH(Expenses!A$3:A$1002)=MONTH(TODAY()))*(YEAR(Expenses!A$3:A$1002)=2026)*(Expenses!A$3:A$1002<>"")*Expenses!D$3:D$1002) -> 0
B29: Others | C29: =SUMPRODUCT((Expenses!C$3:C$1002="Others")*(Expenses!E$3:E$1002="GBP")*(MONTH(Expenses!A$3:A$1002)=MONTH(TODAY()))*(YEAR(Expenses!A$3:A$1002)=2026)*(Expenses!A$3:A$1002<>"")*Expenses!D$3:D$1002) -> 0
B30: Gifts | C30: =SUMPRODUCT((Expenses!C$3:C$1002="Gifts")*(Expenses!E$3:E$1002="GBP")*(MONTH(Expenses!A$3:A$1002)=MONTH(TODAY()))*(YEAR(Expenses!A$3:A$1002)=2026)*(Expenses!A$3:A$1002<>"")*Expenses!D$3:D$1002) -> 0
B31: Donations | C31: =SUMPRODUCT((Expenses!C$3:C$1002="Donations")*(Expenses!E$3:E$1002="GBP")*(MONTH(Expenses!A$3:A$1002)=MONTH(TODAY()))*(YEAR(Expenses!A$3:A$1002)=2026)*(Expenses!A$3:A$1002<>"")*Expenses!D$3:D$1002) -> 0
B32: Investments | C32: =SUMPRODUCT((Expenses!C$3:C$1002="Investments")*(Expenses!E$3:E$1002="GBP")*(MONTH(Expenses!A$3:A$1002)=MONTH(TODAY()))*(YEAR(Expenses!A$3:A$1002)=2026)*(Expenses!A$3:A$1002<>"")*Expenses!D$3:D$1002) -> 0

Sheet Accounts
A1: MASTER ACCOUNT LIST
A2: Account Name | B2: Account Type | C2: Currency | D2: Card Last 4 Digits | E2: Bank/Provider | F2: Opening Balance / Credit Limit | G2: Status | H2: Date Opened | I2: Notes
A3: Lloyds Bank (GBP) | B3: Bank Account | C3: GBP | G3: Active
A4: HSBC Bank (GBP) | B4: Bank Account | C4: GBP | G4: Active
A5: Barclays Bank (GBP) | B5: Bank Account | C5: GBP | G5: Active
A6: Halifax Bank (GBP) | B6: Bank Account | C6: GBP | G6: Active
A7: Klarna Pay (GBP) | B7: Pay Later | C7: GBP | G7: Active
A8: Capitol One Credit Card (GBP) | B8: Credit Card | C8: GBP | G8: Active
A9: HSBC Rewards Credit Card (GBP) | B9: Credit Card | C9: GBP | G9: Active
A10: Barclays Rewards Credit Card (GBP) | B10: Credit Card | C10: GBP | G10: Active
A11: Klarna Pay Later (GBP) | B11: Credit Card | C11: GBP | G11: Active
A12: Splitwise (GBP) | B12: Expense Sharing | C12: GBP | G12: Active
A13: Oyster Travel Card (GBP) | B13: Travel Card | C13: GBP | G13: Active
A14: HDFC Bank (INR) | B14: Bank Account | C14: INR | G14: Active
... A17: Axis Airtel Credit Card (INR) | B17: Credit Card | C17: INR | G17: Active

Sheet Expenses
A1: EXPENSE TRACKER
A2: Date | B2: Name/Description | C2: Category | D2: Price | E2: Currency | F2: Transaction Gateway | G2: Splitwise | H2: Your Share | I2: Recurring | J2: Notes
E3: =IF(F3="","",IF(OR(F3="HDFC Bank (INR)",F3="HDFC IOCL Credit Card (INR)",F3="HDFC Swiggy Credit Card (INR)",F3="Axis Airtel Credit Card (INR)"),"INR","GBP")) | H3: =IF(G3="Yes","",D3) -> 0
E4: =IF(F4="","",IF(OR(F4="HDFC Bank (INR)",F4="HDFC IOCL Credit Card (INR)",F4="HDFC Swiggy Credit Card (INR)",F4="Axis Airtel Credit Card (INR)"),"INR","GBP")) | H4: =IF(G4="Yes","",D4) -> 0
E5: =IF(F5="","",IF(OR(F5="HDFC Bank (INR)",F5="HDFC IOCL Credit Card (INR)",F5="HDFC Swiggy Credit Card (INR)",F5="Axis Airtel Credit Card (INR)"),"INR","GBP")) | H5: =IF(G5="Yes","",D5) -> 0
E6: =IF(F6="","",IF(OR(F6="HDFC Bank (INR)",F6="HDFC IOCL Credit Card (INR)",F6="HDFC Swiggy Credit Card (INR)",F6="Axis Airtel Credit Card (INR)"),"INR","GBP")) | H6: =IF(G6="Yes","",D6) -> 0
E7: =IF(F7="","",IF(OR(F7="HDFC Bank (INR)",F7="HDFC IOCL Credit Card (INR)",F7="HDFC Swiggy Credit Card (INR)",F7="Axis Airtel Credit Card (INR)"),"INR","GBP")) | H7: =IF(G7="Yes","",D7) -> 0
E8: =IF(F8="","",IF(OR(F8="HDFC Bank (INR)",F8="HDFC IOCL Credit Card (INR)",F8="HDFC Swiggy Credit Card (INR)",F8="Axis Airtel Credit Card (INR)"),"INR","GBP")) | H8: =IF(G8="Yes","",D8) -> 0
E9: =IF(F9="","",IF(OR(F9="HDFC Bank (INR)",F9="HDFC IOCL Credit Card (INR)",F9="HDFC Swiggy Credit Card (INR)",F9="Axis Airtel Credit Card (INR)"),"INR","GBP")) | H9: =IF(G9="Yes","",D9) -> 0
E10: =IF(F10="","",IF(OR(F10="HDFC Bank (INR)",F10="HDFC IOCL Credit Card (INR)",F10="HDFC Swiggy Credit Card (INR)",F10="Axis Airtel Credit Card (INR)"),"INR","GBP")) | H10: =IF(G10="Yes","",D10) -> 0
E11: =IF(F11="","",IF(OR(F11="HDFC Bank (INR)",F11="HDFC IOCL Credit Card (INR)",F11="HDFC Swiggy Credit Card (INR)",F11="Axis Airtel Credit Card (INR)"),"INR","GBP")) | H11: =IF(G11="Yes","",D11) -> 0
E12: =IF(F12="","",IF(OR(F12="HDFC Bank (INR)",F12="HDFC IOCL Credit Card (INR)",F12="HDFC Swiggy Credit Card (INR)",F12="Axis Airtel Credit Card (INR)"),"INR","GBP")) | H12: =IF(G12="Yes","",D12) -> 0
E13: =IF(F13="","",IF(OR(F13="HDFC Bank (INR)",F13="HDFC IOCL Credit Card (INR)",F13="HDFC Swiggy Credit Card (INR)",F13="Axis Airtel Credit Card (INR)"),"INR","GBP")) | H13: =IF(G13="Yes","",D13) -> 0
E14: =IF(F14="","",IF(OR(F14="HDFC Bank (INR)",F14="HDFC IOCL Credit Card (INR)",F14="HDFC Swiggy Credit Card (INR)",F14="Axis Airtel Credit Card (INR)"),"INR","GBP")) | H14: =IF(G14="Yes","",D14) -> 0
... E1002: =IF(F1002="","",IF(OR(F1002="HDFC Bank (INR)",F1002="HDFC IOCL Credit Card (INR)",F1002="HDFC Swiggy Credit Card (INR)",F1002="Axis Airtel Credit Card (INR)"),"INR","GBP")) | H1002: =IF(G1002="Yes","",D1002) -> 0

Sheet Income
A1: INCOME TRACKER
A2: Date of Credit | B2: Company | C2: Amount | D2: Currency | E2: Bank Account Credited | F2: Pay Cycle Start | G2: Pay Cycle End
D3: =IF(E3="","",IF(E3="HDFC Bank (INR)","INR","GBP"))
D4: =IF(E4="","",IF(E4="HDFC Bank (INR)","INR","GBP"))
D5: =IF(E5="","",IF(E5="HDFC Bank (INR)","INR","GBP"))
D6: =IF(E6="","",IF(E6="HDFC Bank (INR)","INR","GBP"))
D7: =IF(E7="","",IF(E7="HDFC Bank (INR)","INR","GBP"))
D8: =IF(E8="","",IF(E8="HDFC Bank (INR)","INR","GBP"))
D9: =IF(E9="","",IF(E9="HDFC Bank (INR)","INR","GBP"))
D10: =IF(E10="","",IF(E10="HDFC Bank (INR)","INR","GBP"))
D11: =IF(E11="","",IF(E11="HDFC Bank (INR)","INR","GBP"))
D12: =IF(E12="","",IF(E12="HDFC Bank (INR)","INR","GBP"))
D13: =IF(E13="","",IF(E13="HDFC Bank (INR)","INR","GBP"))
D14: =IF(E14="","",IF(E14="HDFC Bank (INR)","INR","GBP"))
... D502: =IF(E502="","",IF(E502="HDFC Bank (INR)","INR","GBP"))

Sheet Transfers
A1: TRANSFERS (Credit Card Payments & Top-ups)
A2: Date | B2: Description | C2: To Account | D2: From Account | E2: Amount | F2: Notes

Sheet Balances
A1: ACCOUNT BALANCES
A2: Account | B2: Type | C2: Currency | D2: Opening Balance / Credit Limit | E2: Total Credits | F2: Total Debits | G2: Current Balance / Available Credit
A3: Lloyds Bank (GBP) | B3: Bank Account | C3: GBP | E3: =SUMIFS(Income!C$3:C$502,Income!E$3:E$502,A3)+SUMIFS(Transfers!E$3:E$502,Transfers!C$3:C$502,A3) -> 0 | F3: =SUMIFS(Expenses!D$3:D$1002,Expenses!F$3:F$1002,A3)+SUMIFS(Transfers!E$3:E$502,Transfers!D$3:D$502,A3) -> 0 | G3: =D3+E3-F3 -> 0
A4: HSBC Bank (GBP) | B4: Bank Account | C4: GBP | E4: =SUMIFS(Income!C$3:C$502,Income!E$3:E$502,A4)+SUMIFS(Transfers!E$3:E$502,Transfers!C$3:C$502,A4) -> 0 | F4: =SUMIFS(Expenses!D$3:D$1002,Expenses!F$3:F$1002,A4)+SUMIFS(Transfers!E$3:E$502,Transfers!D$3:D$502,A4) -> 0 | G4: =D4+E4-F4 -> 0
A5: Barclays Bank (GBP) | B5: Bank Account | C5: GBP | E5: =SUMIFS(Income!C$3:C$502,Income!E$3:E$502,A5)+SUMIFS(Transfers!E$3:E$502,Transfers!C$3:C$502,A5) -> 0 | F5: =SUMIFS(Expenses!D$3:D$1002,Expenses!F$3:F$1002,A5)+SUMIFS(Transfers!E$3:E$502,Transfers!D$3:D$502,A5) -> 0 | G5: =D5+E5-F5 -> 0
A6: Halifax Bank (GBP) | B6: Bank Account | C6: GBP | E6: =SUMIFS(Income!C$3:C$502,Income!E$3:E$502,A6)+SUMIFS(Transfers!E$3:E$502,Transfers!C$3:C$502,A6) -> 0 | F6: =SUMIFS(Expenses!D$3:D$1002,Expenses!F$3:F$1002,A6)+SUMIFS(Transfers!E$3:E$502,Transfers!D$3:D$502,A6) -> 0 | G6: =D6+E6-F6 -> 0
A7: Klarna Pay (GBP) | B7: Pay Later | C7: GBP | E7: =SUMIFS(Income!C$3:C$502,Income!E$3:E$502,A7)+SUMIFS(Transfers!E$3:E$502,Transfers!C$3:C$502,A7) -> 0 | F7: =SUMIFS(Expenses!D$3:D$1002,Expenses!F$3:F$1002,A7)+SUMIFS(Transfers!E$3:E$502,Transfers!D$3:D$502,A7) -> 0 | G7: =D7-F7+E7 -> 0
A8: Capitol One Credit Card (GBP) | B8: Credit Card | C8: GBP | E8: =SUMIFS(Income!C$3:C$502,Income!E$3:E$502,A8)+SUMIFS(Transfers!E$3:E$502,Transfers!C$3:C$502,A8) -> 0 | F8: =SUMIFS(Expenses!D$3:D$1002,Expenses!F$3:F$1002,A8)+SUMIFS(Transfers!E$3:E$502,Transfers!D$3:D$502,A8) -> 0 | G8: =D8-F8+E8 -> 0
A9: HSBC Rewards Credit Card (GBP) | B9: Credit Card | C9: GBP | E9: =SUMIFS(Income!C$3:C$502,Income!E$3:E$502,A9)+SUMIFS(Transfers!E$3:E$502,Transfers!C$3:C$502,A9) -> 0 | F9: =SUMIFS(Expenses!D$3:D$1002,Expenses!F$3:F$1002,A9)+SUMIFS(Transfers!E$3:E$502,Transfers!D$3:D$502,A9) -> 0 | G9: =D9-F9+E9 -> 0
A10: Barclays Rewards Credit Card (GBP) | B10: Credit Card | C10: GBP | E10: =SUMIFS(Income!C$3:C$502,Income!E$3:E$502,A10)+SUMIFS(Transfers!E$3:E$502,Transfers!C$3:C$502,A10) -> 0 | F10: =SUMIFS(Expenses!D$3:D$1002,Expenses!F$3:F$1002,A10)+SUMIFS(Transfers!E$3:E$502,Transfers!D$3:D$502,A10) -> 0 | G10: =D10-F10+E10 -> 0
A11: Klarna Pay Later (GBP) | B11: Credit Card | C11: GBP | E11: =SUMIFS(Income!C$3:C$502,Income!E$3:E$502,A11)+SUMIFS(Transfers!E$3:E$502,Transfers!C$3:C$502,A11) -> 0 | F11: =SUMIFS(Expenses!D$3:D$1002,Expenses!F$3:F$1002,A11)+SUMIFS(Transfers!E$3:E$502,Transfers!D$3:D$502,A11) -> 0 | G11: =D11-F11+E11 -> 0
A12: Splitwise (GBP) | B12: Expense Sharing | C12: GBP | E12: =SUMPRODUCT((Expenses!G$3:G$1002="Yes")*(Expenses!D$3:D$1002-Expenses!H$3:H$1002))+SUMIFS(Transfers!E$3:E$502,Transfers!C$3:C$502,A12) -> 0 | F12: =SUMIFS(Expenses!D$3:D$1002,Expenses!F$3:F$1002,A12)+SUMIFS(Transfers!E$3:E$502,Transfers!D$3:D$502,A12) -> 0 | G12: =D12+E12-F12 -> 0
A13: Oyster Travel Card (GBP) | B13: Travel Card | C13: GBP | E13: =SUMIFS(Income!C$3:C$502,Income!E$3:E$502,A13)+SUMIFS(Transfers!E$3:E$502,Transfers!C$3:C$502,A13) -> 0 | F13: =SUMIFS(Expenses!D$3:D$1002,Expenses!F$3:F$1002,A13)+SUMIFS(Transfers!E$3:E$502,Transfers!D$3:D$502,A13) -> 0 | G13: =D13+E13-F13 -> 0
A14: HDFC Bank (INR) | B14: Bank Account | C14: INR | E14: =SUMIFS(Income!C$3:C$502,Income!E$3:E$502,A14)+SUMIFS(Transfers!E$3:E$502,Transfers!C$3:C$502,A14) -> 0 | F14: =SUMIFS(Expenses!D$3:D$1002,Expenses!F$3:F$1002,A14)+SUMIFS(Transfers!E$3:E$502,Transfers!D$3:D$502,A14) -> 0 | G14: =D14+E14-F14 -> 0
A15: HDFC IOCL Credit Card (INR) | B15: Credit Card | C15: INR | E15: =SUMIFS(Income!C$3:C$502,Income!E$3:E$502,A15)+SUMIFS(Transfers!E$3:E$502,Transfers!C$3:C$502,A15) -> 0 | F15: =SUMIFS(Expenses!D$3:D$1002,Expenses!F$3:F$1002,A15)+SUMIFS(Transfers!E$3:E$502,Transfers!D$3:D$502,A15) -> 0 | G15: =D15-F15+E15 -> 0
A16: HDFC Swiggy Credit Card (INR) | B16: Credit Card | C16: INR | E16: =SUMIFS(Income!C$3:C$502,Income!E$3:E$502,A16)+SUMIFS(Transfers!E$3:E$502,Transfers!C$3:C$502,A16) -> 0 | F16: =SUMIFS(Expenses!D$3:D$1002,Expenses!F$3:F$1002,A16)+SUMIFS(Transfers!E$3:E$502,Transfers!D$3:D$502,A16) -> 0 | G16: =D16-F16+E16 -> 0
A17: Axis Airtel Credit Card (INR) | B17: Credit Card | C17: INR | E17: =SUMIFS(Income!C$3:C$502,Income!E$3:E$502,A17)+SUMIFS(Transfers!E$3:E$502,Transfers!C$3:C$502,A17) -> 0 | F17: =SUMIFS(Expenses!D$3:D$1002,Expenses!F$3:F$1002,A17)+SUMIFS(Transfers!E$3:E$502,Transfers!D$3:D$502,A17) -> 0 | G17: =D17-F17+E17 -> 0
A20: DASHBOARD SUMMARY
A21: Total GBP Bank Assets | B21: =SUMPRODUCT((C3:C17="GBP")*(B3:B17="Bank Account")*G3:G17)+SUMPRODUCT((C3:C17="GBP")*(B3:B17="Travel Card")*G3:G17)+SUMPRODUCT((C3:C17="GBP")*(B3:B17="Expense Sharing")*G3:G17) -> 0
A22: Total GBP Credit Card Debt | B22: =SUMIFS(F3:F17,C3:C17,"GBP",B3:B17,"Credit Card")+SUMIFS(F3:F17,C3:C17,"GBP",B3:B17,"Pay Later")-SUMIFS(E3:E17,C3:C17,"GBP",B3:B17,"Credit Card")-SUMIFS(E3:E17,C3:C17,"GBP",B3:B17,"Pay Later") -> 0
A23: Total INR Bank Assets | B23: =SUMPRODUCT((C3:C17="INR")*(B3:B17="Bank Account")*G3:G17) -> 0
A24: Total INR Credit Card Debt | B24: =SUMIFS(F3:F17,C3:C17,"INR",B3:B17,"Credit Card")-SUMIFS(E3:E17,C3:C17,"INR",B3:B17,"Credit Card") -> 0
A25: Exchange Rate (GBP to INR) | B25: =Settings!B4 -> 107
A26: Approx Combined GBP Equivalent | B26: =B21-B22+(B23-B24)/B25 -> 0

Sheet Monthly Overview GBP
A1: MONTHLY OVERVIEW (GBP)
A2: Month | B2: Rent | C2: Transport | D2: Travel | E2: Shopping | F2: Electronics | G2: Subscriptions | H2: Bills | I2: Entertainment | J2: Food and Drinks | K2: Groceries | L2: Others | M2: Gifts | N2: Donations | O2: Investments | P2: Total Expenditure | Q2: Income | R2: Gross Savings
A3: January 2026 | B3: =SUMPRODUCT((Expenses!C$3:C$1002="Rent")*(Expenses!E$3:E$1002="GBP")*(MONTH(Expenses!A$3:A$1002)=1)*(YEAR(Expenses!A$3:A$1002)=2026)*(Expenses!A$3:A$1002<>"")*(IF(Expenses!G$3:G$1002="Yes",Expenses!H$3:H$1002,Expenses!D$3:D$1002))) -> 0 | C3: =SUMPRODUCT((Expenses!C$3:C$1002="Transport")*(Expenses!E$3:E$1002="GBP")*(MONTH(Expenses!A$3:A$1002)=1)*(YEAR(Expenses!A$3:A$1002)=2026)*(Expenses!A$3:A$1002<>"")*(IF(Expenses!G$3:G$1002="Yes",Expenses!H$3:H$1002,Expenses!D$3:D$1002))) -> 0 | D3: =SUMPRODUCT((Expenses!C$3:C$1002="Travel")*(Expenses!E$3:E$1002="GBP")*(MONTH(Expenses!A$3:A$1002)=1)*(YEAR(Expenses!A$3:A$1002)=2026)*(Expenses!A$3:A$1002<>"")*(IF(Expenses!G$3:G$1002="Yes",Expenses!H$3:H$1002,Expenses!D$3:D$1002))) -> 0 | E3: =SUMPRODUCT((Expenses!C$3:C$1002="Shopping")*(Expenses!E$3:E$1002="GBP")*(MONTH(Expenses!A$3:A$1002)=1)*(YEAR(Expenses!A$3:A$1002)=2026)*(Expenses!A$3:A$1002<>"")*(IF(Expenses!G$3:G$1002="Yes",Expenses!H$3:H$1002,Expenses!D$3:D$1002))) -> 0 | F3: =SUMPRODUCT((Expenses!C$3:C$1002="Electronics")*(Expenses!E$3:E$1002="GBP")*(MONTH(Expenses!A$3:A$1002)=1)*(YEAR(Expenses!A$3:A$1002)=2026)*(Expenses!A$3:A$1002<>"")*(IF(Expenses!G$3:G$1002="Yes",Expenses!H$3:H$1002,Expenses!D$3:D$1002))) -> 0 | G3: =SUMPRODUCT((Expenses!C$3:C$1002="Subscriptions")*(Expenses!E$3:E$1002="GBP")*(MONTH(Expenses!A$3:A$1002)=1)*(YEAR(Expenses!A$3:A$1002)=2026)*(Expenses!A$3:A$1002<>"")*(IF(Expenses!G$3:G$1002="Yes",Expenses!H$3:H$1002,Expenses!D$3:D$1002))) -> 0 | H3: =SUMPRODUCT((Expenses!C$3:C$1002="Bills")*(Expenses!E$3:E$1002="GBP")*(MONTH(Expenses!A$3:A$1002)=1)*(YEAR(Expenses!A$3:A$1002)=2026)*(Expenses!A$3:A$1002<>"")*(IF(Expenses!G$3:G$1002="Yes",Expenses!H$3:H$1002,Expenses!D$3:D$1002))) -> 0 | I3: =SUMPRODUCT((Expenses!C$3:C$1002="Entertainment")*(Expenses!E$3:E$1002="GBP")*(MONTH(Expenses!A$3:A$1002)=1)*(YEAR(Expenses!A$3:A$1002)=2026)*(Expenses!A$3:A$1002<>"")*(IF(Expenses!G$3:G$1002="Yes",Expenses!H$3:H$1002,Expenses!D$3:D$1002))) -> 0 | J3: =SUMPRODUCT((Expenses!C$3:C$1002="Food and Drinks")*(Expenses!E$3:E$1002="GBP")*(MONTH(Expenses!A$3:A$1002)=1)*(YEAR(Expenses!A$3:A$1002)=2026)*(Expenses!A$3:A$1002<>"")*(IF(Expenses!G$3:G$1002="Yes",Expenses!H$3:H$1002,Expenses!D$3:D$1002))) -> 0 | K3: =SUMPRODUCT((Expenses!C$3:C$1002="Groceries")*(Expenses!E$3:E$1002="GBP")*(MONTH(Expenses!A$3:A$1002)=1)*(YEAR(Expenses!A$3:A$1002)=2026)*(Expenses!A$3:A$1002<>"")*(IF(Expenses!G$3:G$1002="Yes",Expenses!H$3:H$1002,Expenses!D$3:D$1002))) -> 0 | L3: =SUMPRODUCT((Expenses!C$3:C$1002="Others")*(Expenses!E$3:E$1002="GBP")*(MONTH(Expenses!A$3:A$1002)=1)*(YEAR(Expenses!A$3:A$1002)=2026)*(Expenses!A$3:A$1002<>"")*(IF(Expenses!G$3:G$1002="Yes",Expenses!H$3:H$1002,Expenses!D$3:D$1002))) -> 0 | M3: =SUMPRODUCT((Expenses!C$3:C$1002="Gifts")*(Expenses!E$3:E$1002="GBP")*(MONTH(Expenses!A$3:A$1002)=1)*(YEAR(Expenses!A$3:A$1002)=2026)*(Expenses!A$3:A$1002<>"")*(IF(Expenses!G$3:G$1002="Yes",Expenses!H$3:H$1002,Expenses!D$3:D$1002))) -> 0 | N3: =SUMPRODUCT((Expenses!C$3:C$1002="Donations")*(Expenses!E$3:E$1002="GBP")*(MONTH(Expenses!A$3:A$1002)=1)*(YEAR(Expenses!A$3:A$1002)=2026)*(Expenses!A$3:A$1002<>"")*(IF(Expenses!G$3:G$1002="Yes",Expenses!H$3:H$1002,Expenses!D$3:D$1002))) -> 0 | O3: =SUMPRODUCT((Expenses!C$3:C$1002="Investments")*(Expenses!E$3:E$1002="GBP")*(MONTH(Expenses!A$3:A$1002)=1)*(YEAR(Expenses!A$3:A$1002)=2026)*(Expenses!A$3:A$1002<>"")*(IF(Expenses!G$3:G$1002="Yes",Expenses!H$3:H$1002,Expenses!D$3:D$1002))) -> 0 | P3: =SUM(B3:O3) -> 0 | Q3: =SUMPRODUCT((Income!D$3:D$502="GBP")*(MONTH(Income!A$3:A$502)=1)*(YEAR(Income!A$3:A$502)=2026)*(Income!A$3:A$502<>"")*Income!C$3:C$502) -> 0 | R3: =Q3-P3 -> 0
A4: February 2026 | B4: =SUMPRODUCT((Expenses!C$3:C$1002="Rent")*(Expenses!E$3:E$1002="GBP")*(MONTH(Expenses!A$3:A$1002)=2)*(YEAR(Expenses!A$3:A$1002)=2026)*(Expenses!A$3:A$1002<>"")*(IF(Expenses!G$3:G$1002="Yes",Expenses!H$3:H$1002,Expenses!D$3:D$1002))) -> 0 | C4: =SUMPRODUCT((Expenses!C$3:C$1002="Transport")*(Expenses!E$3:E$1002="GBP")*(MONTH(Expenses!A$3:A$1002)=2)*(YEAR(Expenses!A$3:A$1002)=2026)*(Expenses!A$3:A$1002<>"")*(IF(Expenses!G$3:G$1002="Yes",Expenses!H$3:H$1002,Expenses!D$3:D$1002))) -> 0 | D4: =SUMPRODUCT((Expenses!C$3:C$1002="Travel")*(Expenses!E$3:E$1002="GBP")*(MONTH(Expenses!A$3:A$1002)=2)*(YEAR(Expenses!A$3:A$1002)=2026)*(Expenses!A$3:A$1002<>"")*(IF(Expenses!G$3:G$1002="Yes",Expenses!H$3:H$1002,Expenses!D$3:D$1002))) -> 0 | E4: =SUMPRODUCT((Expenses!C$3:C$1002="Shopping")*(Expenses!E$3:E$1002="GBP")*(MONTH(Expenses!A$3:A$1002)=2)*(YEAR(Expenses!A$3:A$1002)=2026)*(Expenses!A$3:A$1002<>"")*(IF(Expenses!G$3:G$1002="Yes",Expenses!H$3:H$1002,Expenses!D$3:D$1002))) -> 0 | F4: =SUMPRODUCT((Expenses!C$3:C$1002="Electronics")*(Expenses!E$3:E$1002="GBP")*(MONTH(Expenses!A$3:A$1002)=2)*(YEAR(Expenses!A$3:A$1002)=2026)*(Expenses!A$3:A$1002<>"")*(IF(Expenses!G$3:G$1002="Yes",Expenses!H$3:H$1002,Expenses!D$3:D$1002))) -> 0 | G4: =SUMPRODUCT((Expenses!C$3:C$1002="Subscriptions")*(Expenses!E$3:E$1002="GBP")*(MONTH(Expenses!A$3:A$1002)=2)*(YEAR(Expenses!A$3:A$1002)=2026)*(Expenses!A$3:A$1002<>"")*(IF(Expenses!G$3:G$1002="Yes",Expenses!H$3:H$1002,Expenses!D$3:D$1002))) -> 0 | H4: =SUMPRODUCT((Expenses!C$3:C$1002="Bills")*(Expenses!E$3:E$1002="GBP")*(MONTH(Expenses!A$3:A$1002)=2)*(YEAR(Expenses!A$3:A$1002)=2026)*(Expenses!A$3:A$1002<>"")*(IF(Expenses!G$3:G$1002="Yes",Expenses!H$3:H$1002,Expenses!D$3:D$1002))) -> 0 | I4: =SUMPRODUCT((Expenses!C$3:C$1002="Entertainment")*(Expenses!E$3:E$1002="GBP")*(MONTH(Expenses!A$3:A$1002)=2)*(YEAR(Expenses!A$3:A$1002)=2026)*(Expenses!A$3:A$1002<>"")*(IF(Expenses!G$3:G$1002="Yes",Expenses!H$3:H$1002,Expenses!D$3:D$1002))) -> 0 | J4: =SUMPRODUCT((Expenses!C$3:C$1002="Food and Drinks")*(Expenses!E$3:E$1002="GBP")*(MONTH(Expenses!A$3:A$1002)=2)*(YEAR(Expenses!A$3:A$1002)=2026)*(Expenses!A$3:A$1002<>"")*(IF(Expenses!G$3:G$1002="Yes",Expenses!H$3:H$1002,Expenses!D$3:D$1002))) -> 0 | K4: =SUMPRODUCT((Expenses!C$3:C$1002="Groceries")*(Expenses!E$3:E$1002="GBP")*(MONTH(Expenses!A$3:A$1002)=2)*(YEAR(Expenses!A$3:A$1002)=2026)*(Expenses!A$3:A$1002<>"")*(IF(Expenses!G$3:G$1002="Yes",Expenses!H$3:H$1002,Expenses!D$3:D$1002))) -> 0 | L4: =SUMPRODUCT((Expenses!C$3:C$1002="Others")*(Expenses!E$3:E$1002="GBP")*(MONTH(Expenses!A$3:A$1002)=2)*(YEAR(Expenses!A$3:A$1002)=2026)*(Expenses!A$3:A$1002<>"")*(IF(Expenses!G$3:G$1002="Yes",Expenses!H$3:H$1002,Expenses!D$3:D$1002))) -> 0 | M4: =SUMPRODUCT((Expenses!C$3:C$1002="Gifts")*(Expenses!E$3:E$1002="GBP")*(MONTH(Expenses!A$3:A$1002)=2)*(YEAR(Expenses!A$3:A$1002)=2026)*(Expenses!A$3:A$1002<>"")*(IF(Expenses!G$3:G$1002="Yes",Expenses!H$3:H$1002,Expenses!D$3:D$1002))) -> 0 | N4: =SUMPRODUCT((Expenses!C$3:C$1002="Donations")*(Expenses!E$3:E$1002="GBP")*(MONTH(Expenses!A$3:A$1002)=2)*(YEAR(Expenses!A$3:A$1002)=2026)*(Expenses!A$3:A$1002<>"")*(IF(Expenses!G$3:G$1002="Yes",Expenses!H$3:H$1002,Expenses!D$3:D$1002))) -> 0 | O4: =SUMPRODUCT((Expenses!C$3:C$1002="Investments")*(Expenses!E$3:E$1002="GBP")*(MONTH(Expenses!A$3:A$1002)=2)*(YEAR(Expenses!A$3:A$1002)=2026)*(Expenses!A$3:A$1002<>"")*(IF(Expenses!G$3:G$1002="Yes",Expenses!H$3:H$1002,Expenses!D$3:D$1002))) -> 0 | P4: =SUM(B4:O4) -> 0 | Q4: =SUMPRODUCT((Income!D$3:D$502="GBP")*(MONTH(Income!A$3:A$502)=2)*(YEAR(Income!A$3:A$502)=2026)*(Income!A$3:A$502<>"")*Income!C$3:C$502) -> 0 | R4: =Q4-P4 -> 0
A5: March 2026 | B5: =SUMPRODUCT((Expenses!C$3:C$1002="Rent")*(Expenses!E$3:E$1002="GBP")*(MONTH(Expenses!A$3:A$1002)=3)*(YEAR(Expenses!A$3:A$1002)=2026)*(Expenses!A$3:A$1002<>"")*(IF(Expenses!G$3:G$1002="Yes",Expenses!H$3:H$1002,Expenses!D$3:D$1002))) -> 0 | C5: =SUMPRODUCT((Expenses!C$3:C$1002="Transport")*(Expenses!E$3:E$1002="GBP")*(MONTH(Expenses!A$3:A$1002)=3)*(YEAR(Expenses!A$3:A$1002)=2026)*(Expenses!A$3:A$1002<>"")*(IF(Expenses!G$3:G$1002="Yes",Expenses!H$3:H$1002,Expenses!D$3:D$1002))) -> 0 | D5: =SUMPRODUCT((Expenses!C$3:C$1002="Travel")*(Expenses!E$3:E$1002="GBP")*(MONTH(Expenses!A$3:A$1002)=3)*(YEAR(Expenses!A$3:A$1002)=2026)*(Expenses!A$3:A$1002<>"")*(IF(Expenses!G$3:G$1002="Yes",Expenses!H$3:H$1002,Expenses!D$3:D$1002))) -> 0 | E5: =SUMPRODUCT((Expenses!C$3:C$1002="Shopping")*(Expenses!E$3:E$1002="GBP")*(MONTH(Expenses!A$3:A$1002)=3)*(YEAR(Expenses!A$3:A$1002)=2026)*(Expenses!A$3:A$1002<>"")*(IF(Expenses!G$3:G$1002="Yes",Expenses!H$3:H$1002,Expenses!D$3:D$1002))) -> 0 | F5: =SUMPRODUCT((Expenses!C$3:C$1002="Electronics")*(Expenses!E$3:E$1002="GBP")*(MONTH(Expenses!A$3:A$1002)=3)*(YEAR(Expenses!A$3:A$1002)=2026)*(Expenses!A$3:A$1002<>"")*(IF(Expenses!G$3:G$1002="Yes",Expenses!H$3:H$1002,Expenses!D$3:D$1002))) -> 0 | G5: =SUMPRODUCT((Expenses!C$3:C$1002="Subscriptions")*(Expenses!E$3:E$1002="GBP")*(MONTH(Expenses!A$3:A$1002)=3)*(YEAR(Expenses!A$3:A$1002)=2026)*(Expenses!A$3:A$1002<>"")*(IF(Expenses!G$3:G$1002="Yes",Expenses!H$3:H$1002,Expenses!D$3:D$1002))) -> 0 | H5: =SUMPRODUCT((Expenses!C$3:C$1002="Bills")*(Expenses!E$3:E$1002="GBP")*(MONTH(Expenses!A$3:A$1002)=3)*(YEAR(Expenses!A$3:A$1002)=2026)*(Expenses!A$3:A$1002<>"")*(IF(Expenses!G$3:G$1002="Yes",Expenses!H$3:H$1002,Expenses!D$3:D$1002))) -> 0 | I5: =SUMPRODUCT((Expenses!C$3:C$1002="Entertainment")*(Expenses!E$3:E$1002="GBP")*(MONTH(Expenses!A$3:A$1002)=3)*(YEAR(Expenses!A$3:A$1002)=2026)*(Expenses!A$3:A$1002<>"")*(IF(Expenses!G$3:G$1002="Yes",Expenses!H$3:H$1002,Expenses!D$3:D$1002))) -> 0 | J5: =SUMPRODUCT((Expenses!C$3:C$1002="Food and Drinks")*(Expenses!E$3:E$1002="GBP")*(MONTH(Expenses!A$3:A$1002)=3)*(YEAR(Expenses!A$3:A$1002)=2026)*(Expenses!A$3:A$1002<>"")*(IF(Expenses!G$3:G$1002="Yes",Expenses!H$3:H$1002,Expenses!D$3:D$1002))) -> 0 | K5: =SUMPRODUCT((Expenses!C$3:C$1002="Groceries")*(Expenses!E$3:E$1002="GBP")*(MONTH(Expenses!A$3:A$1002)=3)*(YEAR(Expenses!A$3:A$1002)=2026)*(Expenses!A$3:A$1002<>"")*(IF(Expenses!G$3:G$1002="Yes",Expenses!H$3:H$1002,Expenses!D$3:D$1002))) -> 0 | L5: =SUMPRODUCT((Expenses!C$3:C$1002="Others")*(Expenses!E$3:E$1002="GBP")*(MONTH(Expenses!A$3:A$1002)=3)*(YEAR(Expenses!A$3:A$1002)=2026)*(Expenses!A$3:A$1002<>"")*(IF(Expenses!G$3:G$1002="Yes",Expenses!H$3:H$1002,Expenses!D$3:D$1002))) -> 0 | M5: =SUMPRODUCT((Expenses!C$3:C$1002="Gifts")*(Expenses!E$3:E$1002="GBP")*(MONTH(Expenses!A$3:A$1002)=3)*(YEAR(Expenses!A$3:A$1002)=2026)*(Expenses!A$3:A$1002<>"")*(IF(Expenses!G$3:G$1002="Yes",Expenses!H$3:H$1002,Expenses!D$3:D$1002))) -> 0 | N5: =SUMPRODUCT((Expenses!C$3:C$1002="Donations")*(Expenses!E$3:E$1002="GBP")*(MONTH(Expenses!A$3:A$1002)=3)*(YEAR(Expenses!A$3:A$1002)=2026)*(Expenses!A$3:A$1002<>"")*(IF(Expenses!G$3:G$1002="Yes",Expenses!H$3:H$1002,Expenses!D$3:D$1002))) -> 0 | O5: =SUMPRODUCT((Expenses!C$3:C$1002="Investments")*(Expenses!E$3:E$1002="GBP")*(MONTH(Expenses!A$3:A$1002)=3)*(YEAR(Expenses!A$3:A$1002)=2026)*(Expenses!A$3:A$1002<>"")*(IF(Expenses!G$3:G$1002="Yes",Expenses!H$3:H$1002,Expenses!D$3:D$1002))) -> 0 | P5: =SUM(B5:O5) -> 0 | Q5: =SUMPRODUCT((Income!D$3:D$502="GBP")*(MONTH(Income!A$3:A$502)=3)*(YEAR(Income!A$3:A$502)=2026)*(Income!A$3:A$502<>"")*Income!C$3:C$502) -> 0 | R5: =Q5-P5 -> 0
A6: April 2026 | B6: =SUMPRODUCT((Expenses!C$3:C$1002="Rent")*(Expenses!E$3:E$1002="GBP")*(MONTH(Expenses!A$3:A$1002)=4)*(YEAR(Expenses!A$3:A$1002)=2026)*(Expenses!A$3:A$1002<>"")*(IF(Expenses!G$3:G$1002="Yes",Expenses!H$3:H$1002,Expenses!D$3:D$1002))) -> 0 | C6: =SUMPRODUCT((Expenses!C$3:C$1002="Transport")*(Expenses!E$3:E$1002="GBP")*(MONTH(Expenses!A$3:A$1002)=4)*(YEAR(Expenses!A$3:A$1002)=2026)*(Expenses!A$3:A$1002<>"")*(IF(Expenses!G$3:G$1002="Yes",Expenses!H$3:H$1002,Expenses!D$3:D$1002))) -> 0 | D6: =SUMPRODUCT((Expenses!C$3:C$1002="Travel")*(Expenses!E$3:E$1002="GBP")*(MONTH(Expenses!A$3:A$1002)=4)*(YEAR(Expenses!A$3:A$1002)=2026)*(Expenses!A$3:A$1002<>"")*(IF(Expenses!G$3:G$1002="Yes",Expenses!H$3:H$1002,Expenses!D$3:D$1002))) -> 0 | E6: =SUMPRODUCT((Expenses!C$3:C$1002="Shopping")*(Expenses!E$3:E$1002="GBP")*(MONTH(Expenses!A$3:A$1002)=4)*(YEAR(Expenses!A$3:A$1002)=2026)*(Expenses!A$3:A$1002<>"")*(IF(Expenses!G$3:G$1002="Yes",Expenses!H$3:H$1002,Expenses!D$3:D$1002))) -> 0 | F6: =SUMPRODUCT((Expenses!C$3:C$1002="Electronics")*(Expenses!E$3:E$1002="GBP")*(MONTH(Expenses!A$3:A$1002)=4)*(YEAR(Expenses!A$3:A$1002)=2026)*(Expenses!A$3:A$1002<>"")*(IF(Expenses!G$3:G$1002="Yes",Expenses!H$3:H$1002,Expenses!D$3:D$1002))) -> 0 | G6: =SUMPRODUCT((Expenses!C$3:C$1002="Subscriptions")*(Expenses!E$3:E$1002="GBP")*(MONTH(Expenses!A$3:A$1002)=4)*(YEAR(Expenses!A$3:A$1002)=2026)*(Expenses!A$3:A$1002<>"")*(IF(Expenses!G$3:G$1002="Yes",Expenses!H$3:H$1002,Expenses!D$3:D$1002))) -> 0 | H6: =SUMPRODUCT((Expenses!C$3:C$1002="Bills")*(Expenses!E$3:E$1002="GBP")*(MONTH(Expenses!A$3:A$1002)=4)*(YEAR(Expenses!A$3:A$1002)=2026)*(Expenses!A$3:A$1002<>"")*(IF(Expenses!G$3:G$1002="Yes",Expenses!H$3:H$1002,Expenses!D$3:D$1002))) -> 0 | I6: =SUMPRODUCT((Expenses!C$3:C$1002="Entertainment")*(Expenses!E$3:E$1002="GBP")*(MONTH(Expenses!A$3:A$1002)=4)*(YEAR(Expenses!A$3:A$1002)=2026)*(Expenses!A$3:A$1002<>"")*(IF(Expenses!G$3:G$1002="Yes",Expenses!H$3:H$1002,Expenses!D$3:D$1002))) -> 0 | J6: =SUMPRODUCT((Expenses!C$3:C$1002="Food and Drinks")*(Expenses!E$3:E$1002="GBP")*(MONTH(Expenses!A$3:A$1002)=4)*(YEAR(Expenses!A$3:A$1002)=2026)*(Expenses!A$3:A$1002<>"")*(IF(Expenses!G$3:G$1002="Yes",Expenses!H$3:H$1002,Expenses!D$3:D$1002))) -> 0 | K6: =SUMPRODUCT((Expenses!C$3:C$1002="Groceries")*(Expenses!E$3:E$1002="GBP")*(MONTH(Expenses!A$3:A$1002)=4)*(YEAR(Expenses!A$3:A$1002)=2026)*(Expenses!A$3:A$1002<>"")*(IF(Expenses!G$3:G$1002="Yes",Expenses!H$3:H$1002,Expenses!D$3:D$1002))) -> 0 | L6: =SUMPRODUCT((Expenses!C$3:C$1002="Others")*(Expenses!E$3:E$1002="GBP")*(MONTH(Expenses!A$3:A$1002)=4)*(YEAR(Expenses!A$3:A$1002)=2026)*(Expenses!A$3:A$1002<>"")*(IF(Expenses!G$3:G$1002="Yes",Expenses!H$3:H$1002,Expenses!D$3:D$1002))) -> 0 | M6: =SUMPRODUCT((Expenses!C$3:C$1002="Gifts")*(Expenses!E$3:E$1002="GBP")*(MONTH(Expenses!A$3:A$1002)=4)*(YEAR(Expenses!A$3:A$1002)=2026)*(Expenses!A$3:A$1002<>"")*(IF(Expenses!G$3:G$1002="Yes",Expenses!H$3:H$1002,Expenses!D$3:D$1002))) -> 0 | N6: =SUMPRODUCT((Expenses!C$3:C$1002="Donations")*(Expenses!E$3:E$1002="GBP")*(MONTH(Expenses!A$3:A$1002)=4)*(YEAR(Expenses!A$3:A$1002)=2026)*(Expenses!A$3:A$1002<>"")*(IF(Expenses!G$3:G$1002="Yes",Expenses!H$3:H$1002,Expenses!D$3:D$1002))) -> 0 | O6: =SUMPRODUCT((Expenses!C$3:C$1002="Investments")*(Expenses!E$3:E$1002="GBP")*(MONTH(Expenses!A$3:A$1002)=4)*(YEAR(Expenses!A$3:A$1002)=2026)*(Expenses!A$3:A$1002<>"")*(IF(Expenses!G$3:G$1002="Yes",Expenses!H$3:H$1002,Expenses!D$3:D$1002))) -> 0 | P6: =SUM(B6:O6) -> 0 | Q6: =SUMPRODUCT((Income!D$3:D$502="GBP")*(MONTH(Income!A$3:A$502)=4)*(YEAR(Income!A$3:A$502)=2026)*(Income!A$3:A$502<>"")*Income!C$3:C$502) -> 0 | R6: =Q6-P6 -> 0
A7: May 2026 | B7: =SUMPRODUCT((Expenses!C$3:C$1002="Rent")*(Expenses!E$3:E$1002="GBP")*(MONTH(Expenses!A$3:A$1002)=5)*(YEAR(Expenses!A$3:A$1002)=2026)*(Expenses!A$3:A$1002<>"")*(IF(Expenses!G$3:G$1002="Yes",Expenses!H$3:H$1002,Expenses!D$3:D$1002))) -> 0 | C7: =SUMPRODUCT((Expenses!C$3:C$1002="Transport")*(Expenses!E$3:E$1002="GBP")*(MONTH(Expenses!A$3:A$1002)=5)*(YEAR(Expenses!A$3:A$1002)=2026)*(Expenses!A$3:A$1002<>"")*(IF(Expenses!G$3:G$1002="Yes",Expenses!H$3:H$1002,Expenses!D$3:D$1002))) -> 0 | D7: =SUMPRODUCT((Expenses!C$3:C$1002="Travel")*(Expenses!E$3:E$1002="GBP")*(MONTH(Expenses!A$3:A$1002)=5)*(YEAR(Expenses!A$3:A$1002)=2026)*(Expenses!A$3:A$1002<>"")*(IF(Expenses!G$3:G$1002="Yes",Expenses!H$3:H$1002,Expenses!D$3:D$1002))) -> 0 | E7: =SUMPRODUCT((Expenses!C$3:C$1002="Shopping")*(Expenses!E$3:E$1002="GBP")*(MONTH(Expenses!A$3:A$1002)=5)*(YEAR(Expenses!A$3:A$1002)=2026)*(Expenses!A$3:A$1002<>"")*(IF(Expenses!G$3:G$1002="Yes",Expenses!H$3:H$1002,Expenses!D$3:D$1002))) -> 0 | F7: =SUMPRODUCT((Expenses!C$3:C$1002="Electronics")*(Expenses!E$3:E$1002="GBP")*(MONTH(Expenses!A$3:A$1002)=5)*(YEAR(Expenses!A$3:A$1002)=2026)*(Expenses!A$3:A$1002<>"")*(IF(Expenses!G$3:G$1002="Yes",Expenses!H$3:H$1002,Expenses!D$3:D$1002))) -> 0 | G7: =SUMPRODUCT((Expenses!C$3:C$1002="Subscriptions")*(Expenses!E$3:E$1002="GBP")*(MONTH(Expenses!A$3:A$1002)=5)*(YEAR(Expenses!A$3:A$1002)=2026)*(Expenses!A$3:A$1002<>"")*(IF(Expenses!G$3:G$1002="Yes",Expenses!H$3:H$1002,Expenses!D$3:D$1002))) -> 0 | H7: =SUMPRODUCT((Expenses!C$3:C$1002="Bills")*(Expenses!E$3:E$1002="GBP")*(MONTH(Expenses!A$3:A$1002)=5)*(YEAR(Expenses!A$3:A$1002)=2026)*(Expenses!A$3:A$1002<>"")*(IF(Expenses!G$3:G$1002="Yes",Expenses!H$3:H$1002,Expenses!D$3:D$1002))) -> 0 | I7: =SUMPRODUCT((Expenses!C$3:C$1002="Entertainment")*(Expenses!E$3:E$1002="GBP")*(MONTH(Expenses!A$3:A$1002)=5)*(YEAR(Expenses!A$3:A$1002)=2026)*(Expenses!A$3:A$1002<>"")*(IF(Expenses!G$3:G$1002="Yes",Expenses!H$3:H$1002,Expenses!D$3:D$1002))) -> 0 | J7: =SUMPRODUCT((Expenses!C$3:C$1002="Food and Drinks")*(Expenses!E$3:E$1002="GBP")*(MONTH(Expenses!A$3:A$1002)=5)*(YEAR(Expenses!A$3:A$1002)=2026)*(Expenses!A$3:A$1002<>"")*(IF(Expenses!G$3:G$1002="Yes",Expenses!H$3:H$1002,Expenses!D$3:D$1002))) -> 0 | K7: =SUMPRODUCT((Expenses!C$3:C$1002="Groceries")*(Expenses!E$3:E$1002="GBP")*(MONTH(Expenses!A$3:A$1002)=5)*(YEAR(Expenses!A$3:A$1002)=2026)*(Expenses!A$3:A$1002<>"")*(IF(Expenses!G$3:G$1002="Yes",Expenses!H$3:H$1002,Expenses!D$3:D$1002))) -> 0 | L7: =SUMPRODUCT((Expenses!C$3:C$1002="Others")*(Expenses!E$3:E$1002="GBP")*(MONTH(Expenses!A$3:A$1002)=5)*(YEAR(Expenses!A$3:A$1002)=2026)*(Expenses!A$3:A$1002<>"")*(IF(Expenses!G$3:G$1002="Yes",Expenses!H$3:H$1002,Expenses!D$3:D$1002))) -> 0 | M7: =SUMPRODUCT((Expenses!C$3:C$1002="Gifts")*(Expenses!E$3:E$1002="GBP")*(MONTH(Expenses!A$3:A$1002)=5)*(YEAR(Expenses!A$3:A$1002)=2026)*(Expenses!A$3:A$1002<>"")*(IF(Expenses!G$3:G$1002="Yes",Expenses!H$3:H$1002,Expenses!D$3:D$1002))) -> 0 | N7: =SUMPRODUCT((Expenses!C$3:C$1002="Donations")*(Expenses!E$3:E$1002="GBP")*(MONTH(Expenses!A$3:A$1002)=5)*(YEAR(Expenses!A$3:A$1002)=2026)*(Expenses!A$3:A$1002<>"")*(IF(Expenses!G$3:G$1002="Yes",Expenses!H$3:H$1002,Expenses!D$3:D$1002))) -> 0 | O7: =SUMPRODUCT((Expenses!C$3:C$1002="Investments")*(Expenses!E$3:E$1002="GBP")*(MONTH(Expenses!A$3:A$1002)=5)*(YEAR(Expenses!A$3:A$1002)=2026)*(Expenses!A$3:A$1002<>"")*(IF(Expenses!G$3:G$1002="Yes",Expenses!H$3:H$1002,Expenses!D$3:D$1002))) -> 0 | P7: =SUM(B7:O7) -> 0 | Q7: =SUMPRODUCT((Income!D$3:D$502="GBP")*(MONTH(Income!A$3:A$502)=5)*(YEAR(Income!A$3:A$502)=2026)*(Income!A$3:A$502<>"")*Income!C$3:C$502) -> 0 | R7: =Q7-P7 -> 0
A8: June 2026 | B8: =SUMPRODUCT((Expenses!C$3:C$1002="Rent")*(Expenses!E$3:E$1002="GBP")*(MONTH(Expenses!A$3:A$1002)=6)*(YEAR(Expenses!A$3:A$1002)=2026)*(Expenses!A$3:A$1002<>"")*(IF(Expenses!G$3:G$1002="Yes",Expenses!H$3:H$1002,Expenses!D$3:D$1002))) -> 0 | C8: =SUMPRODUCT((Expenses!C$3:C$1002="Transport")*(Expenses!E$3:E$1002="GBP")*(MONTH(Expenses!A$3:A$1002)=6)*(YEAR(Expenses!A$3:A$1002)=2026)*(Expenses!A$3:A$1002<>"")*(IF(Expenses!G$3:G$1002="Yes",Expenses!H$3:H$1002,Expenses!D$3:D$1002))) -> 0 | D8: =SUMPRODUCT((Expenses!C$3:C$1002="Travel")*(Expenses!E$3:E$1002="GBP")*(MONTH(Expenses!A$3:A$1002)=6)*(YEAR(Expenses!A$3:A$1002)=2026)*(Expenses!A$3:A$1002<>"")*(IF(Expenses!G$3:G$1002="Yes",Expenses!H$3:H$1002,Expenses!D$3:D$1002))) -> 0 | E8: =SUMPRODUCT((Expenses!C$3:C$1002="Shopping")*(Expenses!E$3:E$1002="GBP")*(MONTH(Expenses!A$3:A$1002)=6)*(YEAR(Expenses!A$3:A$1002)=2026)*(Expenses!A$3:A$1002<>"")*(IF(Expenses!G$3:G$1002="Yes",Expenses!H$3:H$1002,Expenses!D$3:D$1002))) -> 0 | F8: =SUMPRODUCT((Expenses!C$3:C$1002="Electronics")*(Expenses!E$3:E$1002="GBP")*(MONTH(Expenses!A$3:A$1002)=6)*(YEAR(Expenses!A$3:A$1002)=2026)*(Expenses!A$3:A$1002<>"")*(IF(Expenses!G$3:G$1002="Yes",Expenses!H$3:H$1002,Expenses!D$3:D$1002))) -> 0 | G8: =SUMPRODUCT((Expenses!C$3:C$1002="Subscriptions")*(Expenses!E$3:E$1002="GBP")*(MONTH(Expenses!A$3:A$1002)=6)*(YEAR(Expenses!A$3:A$1002)=2026)*(Expenses!A$3:A$1002<>"")*(IF(Expenses!G$3:G$1002="Yes",Expenses!H$3:H$1002,Expenses!D$3:D$1002))) -> 0 | H8: =SUMPRODUCT((Expenses!C$3:C$1002="Bills")*(Expenses!E$3:E$1002="GBP")*(MONTH(Expenses!A$3:A$1002)=6)*(YEAR(Expenses!A$3:A$1002)=2026)*(Expenses!A$3:A$1002<>"")*(IF(Expenses!G$3:G$1002="Yes",Expenses!H$3:H$1002,Expenses!D$3:D$1002))) -> 0 | I8: =SUMPRODUCT((Expenses!C$3:C$1002="Entertainment")*(Expenses!E$3:E$1002="GBP")*(MONTH(Expenses!A$3:A$1002)=6)*(YEAR(Expenses!A$3:A$1002)=2026)*(Expenses!A$3:A$1002<>"")*(IF(Expenses!G$3:G$1002="Yes",Expenses!H$3:H$1002,Expenses!D$3:D$1002))) -> 0 | J8: =SUMPRODUCT((Expenses!C$3:C$1002="Food and Drinks")*(Expenses!E$3:E$1002="GBP")*(MONTH(Expenses!A$3:A$1002)=6)*(YEAR(Expenses!A$3:A$1002)=2026)*(Expenses!A$3:A$1002<>"")*(IF(Expenses!G$3:G$1002="Yes",Expenses!H$3:H$1002,Expenses!D$3:D$1002))) -> 0 | K8: =SUMPRODUCT((Expenses!C$3:C$1002="Groceries")*(Expenses!E$3:E$1002="GBP")*(MONTH(Expenses!A$3:A$1002)=6)*(YEAR(Expenses!A$3:A$1002)=2026)*(Expenses!A$3:A$1002<>"")*(IF(Expenses!G$3:G$1002="Yes",Expenses!H$3:H$1002,Expenses!D$3:D$1002))) -> 0 | L8: =SUMPRODUCT((Expenses!C$3:C$1002="Others")*(Expenses!E$3:E$1002="GBP")*(MONTH(Expenses!A$3:A$1002)=6)*(YEAR(Expenses!A$3:A$1002)=2026)*(Expenses!A$3:A$1002<>"")*(IF(Expenses!G$3:G$1002="Yes",Expenses!H$3:H$1002,Expenses!D$3:D$1002))) -> 0 | M8: =SUMPRODUCT((Expenses!C$3:C$1002="Gifts")*(Expenses!E$3:E$1002="GBP")*(MONTH(Expenses!A$3:A$1002)=6)*(YEAR(Expenses!A$3:A$1002)=2026)*(Expenses!A$3:A$1002<>"")*(IF(Expenses!G$3:G$1002="Yes",Expenses!H$3:H$1002,Expenses!D$3:D$1002))) -> 0 | N8: =SUMPRODUCT((Expenses!C$3:C$1002="Donations")*(Expenses!E$3:E$1002="GBP")*(MONTH(Expenses!A$3:A$1002)=6)*(YEAR(Expenses!A$3:A$1002)=2026)*(Expenses!A$3:A$1002<>"")*(IF(Expenses!G$3:G$1002="Yes",Expenses!H$3:H$1002,Expenses!D$3:D$1002))) -> 0 | O8: =SUMPRODUCT((Expenses!C$3:C$1002="Investments")*(Expenses!E$3:E$1002="GBP")*(MONTH(Expenses!A$3:A$1002)=6)*(YEAR(Expenses!A$3:A$1002)=2026)*(Expenses!A$3:A$1002<>"")*(IF(Expenses!G$3:G$1002="Yes",Expenses!H$3:H$1002,Expenses!D$3:D$1002))) -> 0 | P8: =SUM(B8:O8) -> 0 | Q8: =SUMPRODUCT((Income!D$3:D$502="GBP")*(MONTH(Income!A$3:A$502)=6)*(YEAR(Income!A$3:A$502)=2026)*(Income!A$3:A$502<>"")*Income!C$3:C$502) -> 0 | R8: =Q8-P8 -> 0
A9: July 2026 | B9: =SUMPRODUCT((Expenses!C$3:C$1002="Rent")*(Expenses!E$3:E$1002="GBP")*(MONTH(Expenses!A$3:A$1002)=7)*(YEAR(Expenses!A$3:A$1002)=2026)*(Expenses!A$3:A$1002<>"")*(IF(Expenses!G$3:G$1002="Yes",Expenses!H$3:H$1002,Expenses!D$3:D$1002))) -> 0 | C9: =SUMPRODUCT((Expenses!C$3:C$1002="Transport")*(Expenses!E$3:E$1002="GBP")*(MONTH(Expenses!A$3:A$1002)=7)*(YEAR(Expenses!A$3:A$1002)=2026)*(Expenses!A$3:A$1002<>"")*(IF(Expenses!G$3:G$1002="Yes",Expenses!H$3:H$1002,Expenses!D$3:D$1002))) -> 0 | D9: =SUMPRODUCT((Expenses!C$3:C$1002="Travel")*(Expenses!E$3:E$1002="GBP")*(MONTH(Expenses!A$3:A$1002)=7)*(YEAR(Expenses!A$3:A$1002)=2026)*(Expenses!A$3:A$1002<>"")*(IF(Expenses!G$3:G$1002="Yes",Expenses!H$3:H$1002,Expenses!D$3:D$1002))) -> 0 | E9: =SUMPRODUCT((Expenses!C$3:C$1002="Shopping")*(Expenses!E$3:E$1002="GBP")*(MONTH(Expenses!A$3:A$1002)=7)*(YEAR(Expenses!A$3:A$1002)=2026)*(Expenses!A$3:A$1002<>"")*(IF(Expenses!G$3:G$1002="Yes",Expenses!H$3:H$1002,Expenses!D$3:D$1002))) -> 0 | F9: =SUMPRODUCT((Expenses!C$3:C$1002="Electronics")*(Expenses!E$3:E$1002="GBP")*(MONTH(Expenses!A$3:A$1002)=7)*(YEAR(Expenses!A$3:A$1002)=2026)*(Expenses!A$3:A$1002<>"")*(IF(Expenses!G$3:G$1002="Yes",Expenses!H$3:H$1002,Expenses!D$3:D$1002))) -> 0 | G9: =SUMPRODUCT((Expenses!C$3:C$1002="Subscriptions")*(Expenses!E$3:E$1002="GBP")*(MONTH(Expenses!A$3:A$1002)=7)*(YEAR(Expenses!A$3:A$1002)=2026)*(Expenses!A$3:A$1002<>"")*(IF(Expenses!G$3:G$1002="Yes",Expenses!H$3:H$1002,Expenses!D$3:D$1002))) -> 0 | H9: =SUMPRODUCT((Expenses!C$3:C$1002="Bills")*(Expenses!E$3:E$1002="GBP")*(MONTH(Expenses!A$3:A$1002)=7)*(YEAR(Expenses!A$3:A$1002)=2026)*(Expenses!A$3:A$1002<>"")*(IF(Expenses!G$3:G$1002="Yes",Expenses!H$3:H$1002,Expenses!D$3:D$1002))) -> 0 | I9: =SUMPRODUCT((Expenses!C$3:C$1002="Entertainment")*(Expenses!E$3:E$1002="GBP")*(MONTH(Expenses!A$3:A$1002)=7)*(YEAR(Expenses!A$3:A$1002)=2026)*(Expenses!A$3:A$1002<>"")*(IF(Expenses!G$3:G$1002="Yes",Expenses!H$3:H$1002,Expenses!D$3:D$1002))) -> 0 | J9: =SUMPRODUCT((Expenses!C$3:C$1002="Food and Drinks")*(Expenses!E$3:E$1002="GBP")*(MONTH(Expenses!A$3:A$1002)=7)*(YEAR(Expenses!A$3:A$1002)=2026)*(Expenses!A$3:A$1002<>"")*(IF(Expenses!G$3:G$1002="Yes",Expenses!H$3:H$1002,Expenses!D$3:D$1002))) -> 0 | K9: =SUMPRODUCT((Expenses!C$3:C$1002="Groceries")*(Expenses!E$3:E$1002="GBP")*(MONTH(Expenses!A$3:A$1002)=7)*(YEAR(Expenses!A$3:A$1002)=2026)*(Expenses!A$3:A$1002<>"")*(IF(Expenses!G$3:G$1002="Yes",Expenses!H$3:H$1002,Expenses!D$3:D$1002))) -> 0 | L9: =SUMPRODUCT((Expenses!C$3:C$1002="Others")*(Expenses!E$3:E$1002="GBP")*(MONTH(Expenses!A$3:A$1002)=7)*(YEAR(Expenses!A$3:A$1002)=2026)*(Expenses!A$3:A$1002<>"")*(IF(Expenses!G$3:G$1002="Yes",Expenses!H$3:H$1002,Expenses!D$3:D$1002))) -> 0 | M9: =SUMPRODUCT((Expenses!C$3:C$1002="Gifts")*(Expenses!E$3:E$1002="GBP")*(MONTH(Expenses!A$3:A$1002)=7)*(YEAR(Expenses!A$3:A$1002)=2026)*(Expenses!A$3:A$1002<>"")*(IF(Expenses!G$3:G$1002="Yes",Expenses!H$3:H$1002,Expenses!D$3:D$1002))) -> 0 | N9: =SUMPRODUCT((Expenses!C$3:C$1002="Donations")*(Expenses!E$3:E$1002="GBP")*(MONTH(Expenses!A$3:A$1002)=7)*(YEAR(Expenses!A$3:A$1002)=2026)*(Expenses!A$3:A$1002<>"")*(IF(Expenses!G$3:G$1002="Yes",Expenses!H$3:H$1002,Expenses!D$3:D$1002))) -> 0 | O9: =SUMPRODUCT((Expenses!C$3:C$1002="Investments")*(Expenses!E$3:E$1002="GBP")*(MONTH(Expenses!A$3:A$1002)=7)*(YEAR(Expenses!A$3:A$1002)=2026)*(Expenses!A$3:A$1002<>"")*(IF(Expenses!G$3:G$1002="Yes",Expenses!H$3:H$1002,Expenses!D$3:D$1002))) -> 0 | P9: =SUM(B9:O9) -> 0 | Q9: =SUMPRODUCT((Income!D$3:D$502="GBP")*(MONTH(Income!A$3:A$502)=7)*(YEAR(Income!A$3:A$502)=2026)*(Income!A$3:A$502<>"")*Income!C$3:C$502) -> 0 | R9: =Q9-P9 -> 0
A10: August 2026 | B10: =SUMPRODUCT((Expenses!C$3:C$1002="Rent")*(Expenses!E$3:E$1002="GBP")*(MONTH(Expenses!A$3:A$1002)=8)*(YEAR(Expenses!A$3:A$1002)=2026)*(Expenses!A$3:A$1002<>"")*(IF(Expenses!G$3:G$1002="Yes",Expenses!H$3:H$1002,Expenses!D$3:D$1002))) -> 0 | C10: =SUMPRODUCT((Expenses!C$3:C$1002="Transport")*(Expenses!E$3:E$1002="GBP")*(MONTH(Expenses!A$3:A$1002)=8)*(YEAR(Expenses!A$3:A$1002)=2026)*(Expenses!A$3:A$1002<>"")*(IF(Expenses!G$3:G$1002="Yes",Expenses!H$3:H$1002,Expenses!D$3:D$1002))) -> 0 | D10: =SUMPRODUCT((Expenses!C$3:C$1002="Travel")*(Expenses!E$3:E$1002="GBP")*(MONTH(Expenses!A$3:A$1002)=8)*(YEAR(Expenses!A$3:A$1002)=2026)*(Expenses!A$3:A$1002<>"")*(IF(Expenses!G$3:G$1002="Yes",Expenses!H$3:H$1002,Expenses!D$3:D$1002))) -> 0 | E10: =SUMPRODUCT((Expenses!C$3:C$1002="Shopping")*(Expenses!E$3:E$1002="GBP")*(MONTH(Expenses!A$3:A$1002)=8)*(YEAR(Expenses!A$3:A$1002)=2026)*(Expenses!A$3:A$1002<>"")*(IF(Expenses!G$3:G$1002="Yes",Expenses!H$3:H$1002,Expenses!D$3:D$1002))) -> 0 | F10: =SUMPRODUCT((Expenses!C$3:C$1002="Electronics")*(Expenses!E$3:E$1002="GBP")*(MONTH(Expenses!A$3:A$1002)=8)*(YEAR(Expenses!A$3:A$1002)=2026)*(Expenses!A$3:A$1002<>"")*(IF(Expenses!G$3:G$1002="Yes",Expenses!H$3:H$1002,Expenses!D$3:D$1002))) -> 0 | G10: =SUMPRODUCT((Expenses!C$3:C$1002="Subscriptions")*(Expenses!E$3:E$1002="GBP")*(MONTH(Expenses!A$3:A$1002)=8)*(YEAR(Expenses!A$3:A$1002)=2026)*(Expenses!A$3:A$1002<>"")*(IF(Expenses!G$3:G$1002="Yes",Expenses!H$3:H$1002,Expenses!D$3:D$1002))) -> 0 | H10: =SUMPRODUCT((Expenses!C$3:C$1002="Bills")*(Expenses!E$3:E$1002="GBP")*(MONTH(Expenses!A$3:A$1002)=8)*(YEAR(Expenses!A$3:A$1002)=2026)*(Expenses!A$3:A$1002<>"")*(IF(Expenses!G$3:G$1002="Yes",Expenses!H$3:H$1002,Expenses!D$3:D$1002))) -> 0 | I10: =SUMPRODUCT((Expenses!C$3:C$1002="Entertainment")*(Expenses!E$3:E$1002="GBP")*(MONTH(Expenses!A$3:A$1002)=8)*(YEAR(Expenses!A$3:A$1002)=2026)*(Expenses!A$3:A$1002<>"")*(IF(Expenses!G$3:G$1002="Yes",Expenses!H$3:H$1002,Expenses!D$3:D$1002))) -> 0 | J10: =SUMPRODUCT((Expenses!C$3:C$1002="Food and Drinks")*(Expenses!E$3:E$1002="GBP")*(MONTH(Expenses!A$3:A$1002)=8)*(YEAR(Expenses!A$3:A$1002)=2026)*(Expenses!A$3:A$1002<>"")*(IF(Expenses!G$3:G$1002="Yes",Expenses!H$3:H$1002,Expenses!D$3:D$1002))) -> 0 | K10: =SUMPRODUCT((Expenses!C$3:C$1002="Groceries")*(Expenses!E$3:E$1002="GBP")*(MONTH(Expenses!A$3:A$1002)=8)*(YEAR(Expenses!A$3:A$1002)=2026)*(Expenses!A$3:A$1002<>"")*(IF(Expenses!G$3:G$1002="Yes",Expenses!H$3:H$1002,Expenses!D$3:D$1002))) -> 0 | L10: =SUMPRODUCT((Expenses!C$3:C$1002="Others")*(Expenses!E$3:E$1002="GBP")*(MONTH(Expenses!A$3:A$1002)=8)*(YEAR(Expenses!A$3:A$1002)=2026)*(Expenses!A$3:A$1002<>"")*(IF(Expenses!G$3:G$1002="Yes",Expenses!H$3:H$1002,Expenses!D$3:D$1002))) -> 0 | M10: =SUMPRODUCT((Expenses!C$3:C$1002="Gifts")*(Expenses!E$3:E$1002="GBP")*(MONTH(Expenses!A$3:A$1002)=8)*(YEAR(Expenses!A$3:A$1002)=2026)*(Expenses!A$3:A$1002<>"")*(IF(Expenses!G$3:G$1002="Yes",Expenses!H$3:H$1002,Expenses!D$3:D$1002))) -> 0 | N10: =SUMPRODUCT((Expenses!C$3:C$1002="Donations")*(Expenses!E$3:E$1002="GBP")*(MONTH(Expenses!A$3:A$1002)=8)*(YEAR(Expenses!A$3:A$1002)=2026)*(Expenses!A$3:A$1002<>"")*(IF(Expenses!G$3:G$1002="Yes",Expenses!H$3:H$1002,Expenses!D$3:D$1002))) -> 0 | O10: =SUMPRODUCT((Expenses!C$3:C$1002="Investments")*(Expenses!E$3:E$1002="GBP")*(MONTH(Expenses!A$3:A$1002)=8)*(YEAR(Expenses!A$3:A$1002)=2026)*(Expenses!A$3:A$1002<>"")*(IF(Expenses!G$3:G$1002="Yes",Expenses!H$3:H$1002,Expenses!D$3:D$1002))) -> 0 | P10: =SUM(B10:O10) -> 0 | Q10: =SUMPRODUCT((Income!D$3:D$502="GBP")*(MONTH(Income!A$3:A$502)=8)*(YEAR(Income!A$3:A$502)=2026)*(Income!A$3:A$502<>"")*Income!C$3:C$502) -> 0 | R10: =Q10-P10 -> 0
A11: September 2026 | B11: =SUMPRODUCT((Expenses!C$3:C$1002="Rent")*(Expenses!E$3:E$1002="GBP")*(MONTH(Expenses!A$3:A$1002)=9)*(YEAR(Expenses!A$3:A$1002)=2026)*(Expenses!A$3:A$1002<>"")*(IF(Expenses!G$3:G$1002="Yes",Expenses!H$3:H$1002,Expenses!D$3:D$1002))) -> 0 | C11: =SUMPRODUCT((Expenses!C$3:C$1002="Transport")*(Expenses!E$3:E$1002="GBP")*(MONTH(Expenses!A$3:A$1002)=9)*(YEAR(Expenses!A$3:A$1002)=2026)*(Expenses!A$3:A$1002<>"")*(IF(Expenses!G$3:G$1002="Yes",Expenses!H$3:H$1002,Expenses!D$3:D$1002))) -> 0 | D11: =SUMPRODUCT((Expenses!C$3:C$1002="Travel")*(Expenses!E$3:E$1002="GBP")*(MONTH(Expenses!A$3:A$1002)=9)*(YEAR(Expenses!A$3:A$1002)=2026)*(Expenses!A$3:A$1002<>"")*(IF(Expenses!G$3:G$1002="Yes",Expenses!H$3:H$1002,Expenses!D$3:D$1002))) -> 0 | E11: =SUMPRODUCT((Expenses!C$3:C$1002="Shopping")*(Expenses!E$3:E$1002="GBP")*(MONTH(Expenses!A$3:A$1002)=9)*(YEAR(Expenses!A$3:A$1002)=2026)*(Expenses!A$3:A$1002<>"")*(IF(Expenses!G$3:G$1002="Yes",Expenses!H$3:H$1002,Expenses!D$3:D$1002))) -> 0 | F11: =SUMPRODUCT((Expenses!C$3:C$1002="Electronics")*(Expenses!E$3:E$1002="GBP")*(MONTH(Expenses!A$3:A$1002)=9)*(YEAR(Expenses!A$3:A$1002)=2026)*(Expenses!A$3:A$1002<>"")*(IF(Expenses!G$3:G$1002="Yes",Expenses!H$3:H$1002,Expenses!D$3:D$1002))) -> 0 | G11: =SUMPRODUCT((Expenses!C$3:C$1002="Subscriptions")*(Expenses!E$3:E$1002="GBP")*(MONTH(Expenses!A$3:A$1002)=9)*(YEAR(Expenses!A$3:A$1002)=2026)*(Expenses!A$3:A$1002<>"")*(IF(Expenses!G$3:G$1002="Yes",Expenses!H$3:H$1002,Expenses!D$3:D$1002))) -> 0 | H11: =SUMPRODUCT((Expenses!C$3:C$1002="Bills")*(Expenses!E$3:E$1002="GBP")*(MONTH(Expenses!A$3:A$1002)=9)*(YEAR(Expenses!A$3:A$1002)=2026)*(Expenses!A$3:A$1002<>"")*(IF(Expenses!G$3:G$1002="Yes",Expenses!H$3:H$1002,Expenses!D$3:D$1002))) -> 0 | I11: =SUMPRODUCT((Expenses!C$3:C$1002="Entertainment")*(Expenses!E$3:E$1002="GBP")*(MONTH(Expenses!A$3:A$1002)=9)*(YEAR(Expenses!A$3:A$1002)=2026)*(Expenses!A$3:A$1002<>"")*(IF(Expenses!G$3:G$1002="Yes",Expenses!H$3:H$1002,Expenses!D$3:D$1002))) -> 0 | J11: =SUMPRODUCT((Expenses!C$3:C$1002="Food and Drinks")*(Expenses!E$3:E$1002="GBP")*(MONTH(Expenses!A$3:A$1002)=9)*(YEAR(Expenses!A$3:A$1002)=2026)*(Expenses!A$3:A$1002<>"")*(IF(Expenses!G$3:G$1002="Yes",Expenses!H$3:H$1002,Expenses!D$3:D$1002))) -> 0 | K11: =SUMPRODUCT((Expenses!C$3:C$1002="Groceries")*(Expenses!E$3:E$1002="GBP")*(MONTH(Expenses!A$3:A$1002)=9)*(YEAR(Expenses!A$3:A$1002)=2026)*(Expenses!A$3:A$1002<>"")*(IF(Expenses!G$3:G$1002="Yes",Expenses!H$3:H$1002,Expenses!D$3:D$1002))) -> 0 | L11: =SUMPRODUCT((Expenses!C$3:C$1002="Others")*(Expenses!E$3:E$1002="GBP")*(MONTH(Expenses!A$3:A$1002)=9)*(YEAR(Expenses!A$3:A$1002)=2026)*(Expenses!A$3:A$1002<>"")*(IF(Expenses!G$3:G$1002="Yes",Expenses!H$3:H$1002,Expenses!D$3:D$1002))) -> 0 | M11: =SUMPRODUCT((Expenses!C$3:C$1002="Gifts")*(Expenses!E$3:E$1002="GBP")*(MONTH(Expenses!A$3:A$1002)=9)*(YEAR(Expenses!A$3:A$1002)=2026)*(Expenses!A$3:A$1002<>"")*(IF(Expenses!G$3:G$1002="Yes",Expenses!H$3:H$1002,Expenses!D$3:D$1002))) -> 0 | N11: =SUMPRODUCT((Expenses!C$3:C$1002="Donations")*(Expenses!E$3:E$1002="GBP")*(MONTH(Expenses!A$3:A$1002)=9)*(YEAR(Expenses!A$3:A$1002)=2026)*(Expenses!A$3:A$1002<>"")*(IF(Expenses!G$3:G$1002="Yes",Expenses!H$3:H$1002,Expenses!D$3:D$1002))) -> 0 | O11: =SUMPRODUCT((Expenses!C$3:C$1002="Investments")*(Expenses!E$3:E$1002="GBP")*(MONTH(Expenses!A$3:A$1002)=9)*(YEAR(Expenses!A$3:A$1002)=2026)*(Expenses!A$3:A$1002<>"")*(IF(Expenses!G$3:G$1002="Yes",Expenses!H$3:H$1002,Expenses!D$3:D$1002))) -> 0 | P11: =SUM(B11:O11) -> 0 | Q11: =SUMPRODUCT((Income!D$3:D$502="GBP")*(MONTH(Income!A$3:A$502)=9)*(YEAR(Income!A$3:A$502)=2026)*(Income!A$3:A$502<>"")*Income!C$3:C$502) -> 0 | R11: =Q11-P11 -> 0
A12: October 2026 | B12: =SUMPRODUCT((Expenses!C$3:C$1002="Rent")*(Expenses!E$3:E$1002="GBP")*(MONTH(Expenses!A$3:A$1002)=10)*(YEAR(Expenses!A$3:A$1002)=2026)*(Expenses!A$3:A$1002<>"")*(IF(Expenses!G$3:G$1002="Yes",Expenses!H$3:H$1002,Expenses!D$3:D$1002))) -> 0 | C12: =SUMPRODUCT((Expenses!C$3:C$1002="Transport")*(Expenses!E$3:E$1002="GBP")*(MONTH(Expenses!A$3:A$1002)=10)*(YEAR(Expenses!A$3:A$1002)=2026)*(Expenses!A$3:A$1002<>"")*(IF(Expenses!G$3:G$1002="Yes",Expenses!H$3:H$1002,Expenses!D$3:D$1002))) -> 0 | D12: =SUMPRODUCT((Expenses!C$3:C$1002="Travel")*(Expenses!E$3:E$1002="GBP")*(MONTH(Expenses!A$3:A$1002)=10)*(YEAR(Expenses!A$3:A$1002)=2026)*(Expenses!A$3:A$1002<>"")*(IF(Expenses!G$3:G$1002="Yes",Expenses!H$3:H$1002,Expenses!D$3:D$1002))) -> 0 | E12: =SUMPRODUCT((Expenses!C$3:C$1002="Shopping")*(Expenses!E$3:E$1002="GBP")*(MONTH(Expenses!A$3:A$1002)=10)*(YEAR(Expenses!A$3:A$1002)=2026)*(Expenses!A$3:A$1002<>"")*(IF(Expenses!G$3:G$1002="Yes",Expenses!H$3:H$1002,Expenses!D$3:D$1002))) -> 0 | F12: =SUMPRODUCT((Expenses!C$3:C$1002="Electronics")*(Expenses!E$3:E$1002="GBP")*(MONTH(Expenses!A$3:A$1002)=10)*(YEAR(Expenses!A$3:A$1002)=2026)*(Expenses!A$3:A$1002<>"")*(IF(Expenses!G$3:G$1002="Yes",Expenses!H$3:H$1002,Expenses!D$3:D$1002))) -> 0 | G12: =SUMPRODUCT((Expenses!C$3:C$1002="Subscriptions")*(Expenses!E$3:E$1002="GBP")*(MONTH(Expenses!A$3:A$1002)=10)*(YEAR(Expenses!A$3:A$1002)=2026)*(Expenses!A$3:A$1002<>"")*(IF(Expenses!G$3:G$1002="Yes",Expenses!H$3:H$1002,Expenses!D$3:D$1002))) -> 0 | H12: =SUMPRODUCT((Expenses!C$3:C$1002="Bills")*(Expenses!E$3:E$1002="GBP")*(MONTH(Expenses!A$3:A$1002)=10)*(YEAR(Expenses!A$3:A$1002)=2026)*(Expenses!A$3:A$1002<>"")*(IF(Expenses!G$3:G$1002="Yes",Expenses!H$3:H$1002,Expenses!D$3:D$1002))) -> 0 | I12: =SUMPRODUCT((Expenses!C$3:C$1002="Entertainment")*(Expenses!E$3:E$1002="GBP")*(MONTH(Expenses!A$3:A$1002)=10)*(YEAR(Expenses!A$3:A$1002)=2026)*(Expenses!A$3:A$1002<>"")*(IF(Expenses!G$3:G$1002="Yes",Expenses!H$3:H$1002,Expenses!D$3:D$1002))) -> 0 | J12: =SUMPRODUCT((Expenses!C$3:C$1002="Food and Drinks")*(Expenses!E$3:E$1002="GBP")*(MONTH(Expenses!A$3:A$1002)=10)*(YEAR(Expenses!A$3:A$1002)=2026)*(Expenses!A$3:A$1002<>"")*(IF(Expenses!G$3:G$1002="Yes",Expenses!H$3:H$1002,Expenses!D$3:D$1002))) -> 0 | K12: =SUMPRODUCT((Expenses!C$3:C$1002="Groceries")*(Expenses!E$3:E$1002="GBP")*(MONTH(Expenses!A$3:A$1002)=10)*(YEAR(Expenses!A$3:A$1002)=2026)*(Expenses!A$3:A$1002<>"")*(IF(Expenses!G$3:G$1002="Yes",Expenses!H$3:H$1002,Expenses!D$3:D$1002))) -> 0 | L12: =SUMPRODUCT((Expenses!C$3:C$1002="Others")*(Expenses!E$3:E$1002="GBP")*(MONTH(Expenses!A$3:A$1002)=10)*(YEAR(Expenses!A$3:A$1002)=2026)*(Expenses!A$3:A$1002<>"")*(IF(Expenses!G$3:G$1002="Yes",Expenses!H$3:H$1002,Expenses!D$3:D$1002))) -> 0 | M12: =SUMPRODUCT((Expenses!C$3:C$1002="Gifts")*(Expenses!E$3:E$1002="GBP")*(MONTH(Expenses!A$3:A$1002)=10)*(YEAR(Expenses!A$3:A$1002)=2026)*(Expenses!A$3:A$1002<>"")*(IF(Expenses!G$3:G$1002="Yes",Expenses!H$3:H$1002,Expenses!D$3:D$1002))) -> 0 | N12: =SUMPRODUCT((Expenses!C$3:C$1002="Donations")*(Expenses!E$3:E$1002="GBP")*(MONTH(Expenses!A$3:A$1002)=10)*(YEAR(Expenses!A$3:A$1002)=2026)*(Expenses!A$3:A$1002<>"")*(IF(Expenses!G$3:G$1002="Yes",Expenses!H$3:H$1002,Expenses!D$3:D$1002))) -> 0 | O12: =SUMPRODUCT((Expenses!C$3:C$1002="Investments")*(Expenses!E$3:E$1002="GBP")*(MONTH(Expenses!A$3:A$1002)=10)*(YEAR(Expenses!A$3:A$1002)=2026)*(Expenses!A$3:A$1002<>"")*(IF(Expenses!G$3:G$1002="Yes",Expenses!H$3:H$1002,Expenses!D$3:D$1002))) -> 0 | P12: =SUM(B12:O12) -> 0 | Q12: =SUMPRODUCT((Income!D$3:D$502="GBP")*(MONTH(Income!A$3:A$502)=10)*(YEAR(Income!A$3:A$502)=2026)*(Income!A$3:A$502<>"")*Income!C$3:C$502) -> 0 | R12: =Q12-P12 -> 0
A13: November 2026 | B13: =SUMPRODUCT((Expenses!C$3:C$1002="Rent")*(Expenses!E$3:E$1002="GBP")*(MONTH(Expenses!A$3:A$1002)=11)*(YEAR(Expenses!A$3:A$1002)=2026)*(Expenses!A$3:A$1002<>"")*(IF(Expenses!G$3:G$1002="Yes",Expenses!H$3:H$1002,Expenses!D$3:D$1002))) -> 0 | C13: =SUMPRODUCT((Expenses!C$3:C$1002="Transport")*(Expenses!E$3:E$1002="GBP")*(MONTH(Expenses!A$3:A$1002)=11)*(YEAR(Expenses!A$3:A$1002)=2026)*(Expenses!A$3:A$1002<>"")*(IF(Expenses!G$3:G$1002="Yes",Expenses!H$3:H$1002,Expenses!D$3:D$1002))) -> 0 | D13: =SUMPRODUCT((Expenses!C$3:C$1002="Travel")*(Expenses!E$3:E$1002="GBP")*(MONTH(Expenses!A$3:A$1002)=11)*(YEAR(Expenses!A$3:A$1002)=2026)*(Expenses!A$3:A$1002<>"")*(IF(Expenses!G$3:G$1002="Yes",Expenses!H$3:H$1002,Expenses!D$3:D$1002))) -> 0 | E13: =SUMPRODUCT((Expenses!C$3:C$1002="Shopping")*(Expenses!E$3:E$1002="GBP")*(MONTH(Expenses!A$3:A$1002)=11)*(YEAR(Expenses!A$3:A$1002)=2026)*(Expenses!A$3:A$1002<>"")*(IF(Expenses!G$3:G$1002="Yes",Expenses!H$3:H$1002,Expenses!D$3:D$1002))) -> 0 | F13: =SUMPRODUCT((Expenses!C$3:C$1002="Electronics")*(Expenses!E$3:E$1002="GBP")*(MONTH(Expenses!A$3:A$1002)=11)*(YEAR(Expenses!A$3:A$1002)=2026)*(Expenses!A$3:A$1002<>"")*(IF(Expenses!G$3:G$1002="Yes",Expenses!H$3:H$1002,Expenses!D$3:D$1002))) -> 0 | G13: =SUMPRODUCT((Expenses!C$3:C$1002="Subscriptions")*(Expenses!E$3:E$1002="GBP")*(MONTH(Expenses!A$3:A$1002)=11)*(YEAR(Expenses!A$3:A$1002)=2026)*(Expenses!A$3:A$1002<>"")*(IF(Expenses!G$3:G$1002="Yes",Expenses!H$3:H$1002,Expenses!D$3:D$1002))) -> 0 | H13: =SUMPRODUCT((Expenses!C$3:C$1002="Bills")*(Expenses!E$3:E$1002="GBP")*(MONTH(Expenses!A$3:A$1002)=11)*(YEAR(Expenses!A$3:A$1002)=2026)*(Expenses!A$3:A$1002<>"")*(IF(Expenses!G$3:G$1002="Yes",Expenses!H$3:H$1002,Expenses!D$3:D$1002))) -> 0 | I13: =SUMPRODUCT((Expenses!C$3:C$1002="Entertainment")*(Expenses!E$3:E$1002="GBP")*(MONTH(Expenses!A$3:A$1002)=11)*(YEAR(Expenses!A$3:A$1002)=2026)*(Expenses!A$3:A$1002<>"")*(IF(Expenses!G$3:G$1002="Yes",Expenses!H$3:H$1002,Expenses!D$3:D$1002))) -> 0 | J13: =SUMPRODUCT((Expenses!C$3:C$1002="Food and Drinks")*(Expenses!E$3:E$1002="GBP")*(MONTH(Expenses!A$3:A$1002)=11)*(YEAR(Expenses!A$3:A$1002)=2026)*(Expenses!A$3:A$1002<>"")*(IF(Expenses!G$3:G$1002="Yes",Expenses!H$3:H$1002,Expenses!D$3:D$1002))) -> 0 | K13: =SUMPRODUCT((Expenses!C$3:C$1002="Groceries")*(Expenses!E$3:E$1002="GBP")*(MONTH(Expenses!A$3:A$1002)=11)*(YEAR(Expenses!A$3:A$1002)=2026)*(Expenses!A$3:A$1002<>"")*(IF(Expenses!G$3:G$1002="Yes",Expenses!H$3:H$1002,Expenses!D$3:D$1002))) -> 0 | L13: =SUMPRODUCT((Expenses!C$3:C$1002="Others")*(Expenses!E$3:E$1002="GBP")*(MONTH(Expenses!A$3:A$1002)=11)*(YEAR(Expenses!A$3:A$1002)=2026)*(Expenses!A$3:A$1002<>"")*(IF(Expenses!G$3:G$1002="Yes",Expenses!H$3:H$1002,Expenses!D$3:D$1002))) -> 0 | M13: =SUMPRODUCT((Expenses!C$3:C$1002="Gifts")*(Expenses!E$3:E$1002="GBP")*(MONTH(Expenses!A$3:A$1002)=11)*(YEAR(Expenses!A$3:A$1002)=2026)*(Expenses!A$3:A$1002<>"")*(IF(Expenses!G$3:G$1002="Yes",Expenses!H$3:H$1002,Expenses!D$3:D$1002))) -> 0 | N13: =SUMPRODUCT((Expenses!C$3:C$1002="Donations")*(Expenses!E$3:E$1002="GBP")*(MONTH(Expenses!A$3:A$1002)=11)*(YEAR(Expenses!A$3:A$1002)=2026)*(Expenses!A$3:A$1002<>"")*(IF(Expenses!G$3:G$1002="Yes",Expenses!H$3:H$1002,Expenses!D$3:D$1002))) -> 0 | O13: =SUMPRODUCT((Expenses!C$3:C$1002="Investments")*(Expenses!E$3:E$1002="GBP")*(MONTH(Expenses!A$3:A$1002)=11)*(YEAR(Expenses!A$3:A$1002)=2026)*(Expenses!A$3:A$1002<>"")*(IF(Expenses!G$3:G$1002="Yes",Expenses!H$3:H$1002,Expenses!D$3:D$1002))) -> 0 | P13: =SUM(B13:O13) -> 0 | Q13: =SUMPRODUCT((Income!D$3:D$502="GBP")*(MONTH(Income!A$3:A$502)=11)*(YEAR(Income!A$3:A$502)=2026)*(Income!A$3:A$502<>"")*Income!C$3:C$502) -> 0 | R13: =Q13-P13 -> 0
